2025-01-04 13:10:18,879 - hardware - CRITICAL - Critical error in CLI mode: 'utf-8' codec can't decode byte 0x86 in position 1: invalid start byte
Traceback (most recent call last):
  File "/home/nate/Python_GUI_TS1500_Probe-B/main.py", line 340, in cli_mode
    if not wait_for_ready(controller):
           ~~~~~~~~~~~~~~^^^^^^^^^^^^
  File "/home/nate/Python_GUI_TS1500_Probe-B/main.py", line 64, in wait_for_ready
    response = controller._arduino.readline().decode('utf-8').strip()
               ~~~~~~~~~~~~~~~~~~~~~~~~~~~~~~~~~~~~~^^^^^^^^^
UnicodeDecodeError: 'utf-8' codec can't decode byte 0x86 in position 1: invalid start byte
2025-01-04 13:39:42,084 - gui - ERROR - Error during homing: 'MainController' object has no attribute 'home'
2025-01-04 13:39:44,175 - gui - ERROR - Error during stop: 'MainController' object has no attribute 'stop'
2025-01-04 13:39:44,176 - gui - ERROR - Error during stop: 'MainController' object has no attribute 'stop'
2025-01-04 13:39:44,637 - gui - ERROR - Error during test: 'MainController' object has no attribute 'run_test'
2025-01-04 13:39:45,255 - gui - ERROR - Error starting test: 'MainController' object has no attribute 'start_test'
2025-01-04 13:39:45,669 - gui - ERROR - Error during emergency stop: 'MainController' object has no attribute 'emergency_stop'
2025-01-04 13:39:48,752 - gui - ERROR - Error moving motor: 'MainController' object has no attribute 'move_motor'
2025-01-04 13:39:48,929 - gui - ERROR - Error moving motor: 'MainController' object has no attribute 'move_motor'
2025-01-04 13:39:49,112 - gui - ERROR - Error moving motor: 'MainController' object has no attribute 'move_motor'
2025-01-04 13:39:49,282 - gui - ERROR - Error moving motor: 'MainController' object has no attribute 'move_motor'
2025-01-04 13:39:49,438 - gui - ERROR - Error moving motor: 'MainController' object has no attribute 'move_motor'
2025-01-04 13:39:49,804 - gui - ERROR - Error moving motor: 'MainController' object has no attribute 'move_motor'
2025-01-04 13:39:49,960 - gui - ERROR - Error moving motor: 'MainController' object has no attribute 'move_motor'
2025-01-04 13:39:50,123 - gui - ERROR - Error moving motor: 'MainController' object has no attribute 'move_motor'
2025-01-04 13:39:50,293 - gui - ERROR - Error moving motor: 'MainController' object has no attribute 'move_motor'
2025-01-04 13:40:36,111 - gui - ERROR - Homing failed
2025-01-04 13:40:36,115 - gui - ERROR - Failed to stop motor
2025-01-04 13:40:36,712 - gui - ERROR - Failed to stop motor
2025-01-04 13:40:36,714 - gui - ERROR - Failed to stop motor
2025-01-04 13:40:36,717 - gui - ERROR - Failed to stop motor
2025-01-04 13:40:36,718 - gui - ERROR - Failed to stop motor
2025-01-04 13:40:36,723 - gui - ERROR - Failed to stop motor
2025-01-04 13:40:36,723 - gui - ERROR - Failed to stop motor
2025-01-04 13:40:36,872 - gui - ERROR - Test already running
2025-01-04 13:40:36,873 - gui - ERROR - Test failed
2025-01-04 13:40:37,029 - gui - ERROR - Test already running
2025-01-04 13:40:37,029 - gui - ERROR - Test failed
2025-01-04 13:40:37,738 - gui - ERROR - Test already running
2025-01-04 13:40:37,894 - gui - ERROR - Test already running
2025-01-04 13:40:52,733 - gui - ERROR - Error during homing: 'NoneType' object cannot be interpreted as an integer
2025-01-04 13:40:52,734 - gui - ERROR - Failed to home system before test
2025-01-04 13:45:41,025 - gui - ERROR - Error during test: Movement error: ERROR: Movement rejected - not homed
2025-01-04 13:45:41,025 - gui - ERROR - Test failed or was interrupted
2025-01-04 13:45:44,036 - gui - ERROR - Error during test: Movement error: ERROR: Movement rejected - not homed
2025-01-04 13:45:44,036 - gui - ERROR - Test failed or was interrupted
2025-01-04 13:45:47,046 - gui - ERROR - Error during test: Movement error: ERROR: Movement rejected - not homed
2025-01-04 13:45:47,047 - gui - ERROR - Test failed or was interrupted
2025-01-04 13:45:50,061 - gui - ERROR - Error during test: Movement error: ERROR: Movement rejected - not homed
2025-01-04 13:45:50,061 - gui - ERROR - Test failed or was interrupted
2025-01-04 13:52:30,655 - gui - ERROR - Error sending command: can't re-enter readline
2025-01-04 14:08:27,770 - hardware - CRITICAL - Critical error in CLI mode: 'utf-8' codec can't decode byte 0xe1 in position 1: invalid continuation byte
Traceback (most recent call last):
  File "/home/nate/Python_GUI_TS1500_Probe-B/main.py", line 343, in cli_mode
    if not wait_for_ready(controller):
           ~~~~~~~~~~~~~~^^^^^^^^^^^^
  File "/home/nate/Python_GUI_TS1500_Probe-B/main.py", line 67, in wait_for_ready
    response = controller._arduino.readline().decode('utf-8').strip()
               ~~~~~~~~~~~~~~~~~~~~~~~~~~~~~~~~~~~~~^^^^^^^^^
UnicodeDecodeError: 'utf-8' codec can't decode byte 0xe1 in position 1: invalid continuation byte
2025-01-04 14:09:02,078 - hardware - CRITICAL - Critical error in CLI mode: 'utf-8' codec can't decode byte 0xb3 in position 0: invalid start byte
Traceback (most recent call last):
  File "/home/nate/Python_GUI_TS1500_Probe-B/main.py", line 343, in cli_mode
    if not wait_for_ready(controller):
           ~~~~~~~~~~~~~~^^^^^^^^^^^^
  File "/home/nate/Python_GUI_TS1500_Probe-B/main.py", line 67, in wait_for_ready
    response = controller._arduino.readline().decode('utf-8').strip()
               ~~~~~~~~~~~~~~~~~~~~~~~~~~~~~~~~~~~~~^^^^^^^^^
UnicodeDecodeError: 'utf-8' codec can't decode byte 0xb3 in position 0: invalid start byte
2025-01-04 15:10:49,208 - root - ERROR - Uncaught exception
Traceback (most recent call last):
  File "/home/nate/Python_GUI_TS1500_Probe-B/gui/main_window.py", line 183, in handle_exit
    self.logger.info("Exit button clicked")
    ~~~~~~~~~~~~~~~~^^^^^^^^^^^^^^^^^^^^^^^
  File "/usr/lib/python3.13/logging/__init__.py", line 1519, in info
    self._log(INFO, msg, args, **kwargs)
    ~~~~~~~~~^^^^^^^^^^^^^^^^^^^^^^^^^^^
  File "/usr/lib/python3.13/logging/__init__.py", line 1664, in _log
    self.handle(record)
    ~~~~~~~~~~~^^^^^^^^
  File "/usr/lib/python3.13/logging/__init__.py", line 1680, in handle
    self.callHandlers(record)
    ~~~~~~~~~~~~~~~~~^^^^^^^^
  File "/usr/lib/python3.13/logging/__init__.py", line 1736, in callHandlers
    hdlr.handle(record)
    ~~~~~~~~~~~^^^^^^^^
  File "/usr/lib/python3.13/logging/__init__.py", line 1026, in handle
    self.emit(record)
    ~~~~~~~~~^^^^^^^^
  File "/home/nate/Python_GUI_TS1500_Probe-B/gui/main_window.py", line 26, in emit
    self.text_edit.append(msg)
    ~~~~~~~~~~~~~~~~~~~~~^^^^^
RuntimeError: wrapped C/C++ object of type QTextEdit has been deleted
2025-01-04 15:10:50,884 - root - ERROR - Uncaught exception
Traceback (most recent call last):
  File "/home/nate/Python_GUI_TS1500_Probe-B/gui/main_window.py", line 183, in handle_exit
    self.logger.info("Exit button clicked")
    ~~~~~~~~~~~~~~~~^^^^^^^^^^^^^^^^^^^^^^^
  File "/usr/lib/python3.13/logging/__init__.py", line 1519, in info
    self._log(INFO, msg, args, **kwargs)
    ~~~~~~~~~^^^^^^^^^^^^^^^^^^^^^^^^^^^
  File "/usr/lib/python3.13/logging/__init__.py", line 1664, in _log
    self.handle(record)
    ~~~~~~~~~~~^^^^^^^^
  File "/usr/lib/python3.13/logging/__init__.py", line 1680, in handle
    self.callHandlers(record)
    ~~~~~~~~~~~~~~~~~^^^^^^^^
  File "/usr/lib/python3.13/logging/__init__.py", line 1736, in callHandlers
    hdlr.handle(record)
    ~~~~~~~~~~~^^^^^^^^
  File "/usr/lib/python3.13/logging/__init__.py", line 1026, in handle
    self.emit(record)
    ~~~~~~~~~^^^^^^^^
  File "/home/nate/Python_GUI_TS1500_Probe-B/gui/main_window.py", line 26, in emit
    self.text_edit.append(msg)
    ~~~~~~~~~~~~~~~~~~~~~^^^^^
RuntimeError: wrapped C/C++ object of type QTextEdit has been deleted
2025-01-04 15:10:50,997 - root - ERROR - Uncaught exception
Traceback (most recent call last):
  File "/home/nate/Python_GUI_TS1500_Probe-B/gui/main_window.py", line 183, in handle_exit
    self.logger.info("Exit button clicked")
    ~~~~~~~~~~~~~~~~^^^^^^^^^^^^^^^^^^^^^^^
  File "/usr/lib/python3.13/logging/__init__.py", line 1519, in info
    self._log(INFO, msg, args, **kwargs)
    ~~~~~~~~~^^^^^^^^^^^^^^^^^^^^^^^^^^^
  File "/usr/lib/python3.13/logging/__init__.py", line 1664, in _log
    self.handle(record)
    ~~~~~~~~~~~^^^^^^^^
  File "/usr/lib/python3.13/logging/__init__.py", line 1680, in handle
    self.callHandlers(record)
    ~~~~~~~~~~~~~~~~~^^^^^^^^
  File "/usr/lib/python3.13/logging/__init__.py", line 1736, in callHandlers
    hdlr.handle(record)
    ~~~~~~~~~~~^^^^^^^^
  File "/usr/lib/python3.13/logging/__init__.py", line 1026, in handle
    self.emit(record)
    ~~~~~~~~~^^^^^^^^
  File "/home/nate/Python_GUI_TS1500_Probe-B/gui/main_window.py", line 26, in emit
    self.text_edit.append(msg)
    ~~~~~~~~~~~~~~~~~~~~~^^^^^
RuntimeError: wrapped C/C++ object of type QTextEdit has been deleted
2025-01-04 15:10:51,157 - root - ERROR - Uncaught exception
Traceback (most recent call last):
  File "/home/nate/Python_GUI_TS1500_Probe-B/gui/main_window.py", line 183, in handle_exit
    self.logger.info("Exit button clicked")
    ~~~~~~~~~~~~~~~~^^^^^^^^^^^^^^^^^^^^^^^
  File "/usr/lib/python3.13/logging/__init__.py", line 1519, in info
    self._log(INFO, msg, args, **kwargs)
    ~~~~~~~~~^^^^^^^^^^^^^^^^^^^^^^^^^^^
  File "/usr/lib/python3.13/logging/__init__.py", line 1664, in _log
    self.handle(record)
    ~~~~~~~~~~~^^^^^^^^
  File "/usr/lib/python3.13/logging/__init__.py", line 1680, in handle
    self.callHandlers(record)
    ~~~~~~~~~~~~~~~~~^^^^^^^^
  File "/usr/lib/python3.13/logging/__init__.py", line 1736, in callHandlers
    hdlr.handle(record)
    ~~~~~~~~~~~^^^^^^^^
  File "/usr/lib/python3.13/logging/__init__.py", line 1026, in handle
    self.emit(record)
    ~~~~~~~~~^^^^^^^^
  File "/home/nate/Python_GUI_TS1500_Probe-B/gui/main_window.py", line 26, in emit
    self.text_edit.append(msg)
    ~~~~~~~~~~~~~~~~~~~~~^^^^^
RuntimeError: wrapped C/C++ object of type QTextEdit has been deleted
2025-01-04 15:10:51,287 - root - ERROR - Uncaught exception
Traceback (most recent call last):
  File "/home/nate/Python_GUI_TS1500_Probe-B/gui/main_window.py", line 183, in handle_exit
    self.logger.info("Exit button clicked")
    ~~~~~~~~~~~~~~~~^^^^^^^^^^^^^^^^^^^^^^^
  File "/usr/lib/python3.13/logging/__init__.py", line 1519, in info
    self._log(INFO, msg, args, **kwargs)
    ~~~~~~~~~^^^^^^^^^^^^^^^^^^^^^^^^^^^
  File "/usr/lib/python3.13/logging/__init__.py", line 1664, in _log
    self.handle(record)
    ~~~~~~~~~~~^^^^^^^^
  File "/usr/lib/python3.13/logging/__init__.py", line 1680, in handle
    self.callHandlers(record)
    ~~~~~~~~~~~~~~~~~^^^^^^^^
  File "/usr/lib/python3.13/logging/__init__.py", line 1736, in callHandlers
    hdlr.handle(record)
    ~~~~~~~~~~~^^^^^^^^
  File "/usr/lib/python3.13/logging/__init__.py", line 1026, in handle
    self.emit(record)
    ~~~~~~~~~^^^^^^^^
  File "/home/nate/Python_GUI_TS1500_Probe-B/gui/main_window.py", line 26, in emit
    self.text_edit.append(msg)
    ~~~~~~~~~~~~~~~~~~~~~^^^^^
RuntimeError: wrapped C/C++ object of type QTextEdit has been deleted
2025-01-04 15:10:51,438 - root - ERROR - Uncaught exception
Traceback (most recent call last):
  File "/home/nate/Python_GUI_TS1500_Probe-B/gui/main_window.py", line 183, in handle_exit
    self.logger.info("Exit button clicked")
    ~~~~~~~~~~~~~~~~^^^^^^^^^^^^^^^^^^^^^^^
  File "/usr/lib/python3.13/logging/__init__.py", line 1519, in info
    self._log(INFO, msg, args, **kwargs)
    ~~~~~~~~~^^^^^^^^^^^^^^^^^^^^^^^^^^^
  File "/usr/lib/python3.13/logging/__init__.py", line 1664, in _log
    self.handle(record)
    ~~~~~~~~~~~^^^^^^^^
  File "/usr/lib/python3.13/logging/__init__.py", line 1680, in handle
    self.callHandlers(record)
    ~~~~~~~~~~~~~~~~~^^^^^^^^
  File "/usr/lib/python3.13/logging/__init__.py", line 1736, in callHandlers
    hdlr.handle(record)
    ~~~~~~~~~~~^^^^^^^^
  File "/usr/lib/python3.13/logging/__init__.py", line 1026, in handle
    self.emit(record)
    ~~~~~~~~~^^^^^^^^
  File "/home/nate/Python_GUI_TS1500_Probe-B/gui/main_window.py", line 26, in emit
    self.text_edit.append(msg)
    ~~~~~~~~~~~~~~~~~~~~~^^^^^
RuntimeError: wrapped C/C++ object of type QTextEdit has been deleted
2025-01-04 15:10:53,652 - root - ERROR - Uncaught exception
Traceback (most recent call last):
  File "/home/nate/Python_GUI_TS1500_Probe-B/gui/main_window.py", line 191, in closeEvent
    self.logger.info("Closing home type dialog")
    ~~~~~~~~~~~~~~~~^^^^^^^^^^^^^^^^^^^^^^^^^^^^
  File "/usr/lib/python3.13/logging/__init__.py", line 1519, in info
    self._log(INFO, msg, args, **kwargs)
    ~~~~~~~~~^^^^^^^^^^^^^^^^^^^^^^^^^^^
  File "/usr/lib/python3.13/logging/__init__.py", line 1664, in _log
    self.handle(record)
    ~~~~~~~~~~~^^^^^^^^
  File "/usr/lib/python3.13/logging/__init__.py", line 1680, in handle
    self.callHandlers(record)
    ~~~~~~~~~~~~~~~~~^^^^^^^^
  File "/usr/lib/python3.13/logging/__init__.py", line 1736, in callHandlers
    hdlr.handle(record)
    ~~~~~~~~~~~^^^^^^^^
  File "/usr/lib/python3.13/logging/__init__.py", line 1026, in handle
    self.emit(record)
    ~~~~~~~~~^^^^^^^^
  File "/home/nate/Python_GUI_TS1500_Probe-B/gui/main_window.py", line 26, in emit
    self.text_edit.append(msg)
    ~~~~~~~~~~~~~~~~~~~~~^^^^^
RuntimeError: wrapped C/C++ object of type QTextEdit has been deleted
2025-01-04 15:20:20,883 - gui - ERROR - Error reading response: 'QTextCursor' object has no attribute 'End'
2025-01-04 15:21:54,739 - gui - ERROR - Error reading response: 'HomingDialog' object has no attribute 'log_message'
